'<?xml version="1.0" ?>
<!-- =================================================================================== -->
<!-- |    This document was autogenerated by xacro from /home/anton/develop/Dr.QP/install/drqp_description/share/drqp_description/urdf/dr_qp.urdf.xacro | -->
<!-- |    EDITING THIS FILE BY HAND IS NOT RECOMMENDED                                 | -->
<!-- =================================================================================== -->
<robot name="dr_qp">
  <material name="drqp_black">
    <texture filename="package://drqp_description/meshes/drqp_black.png"/>
  </material>
  <material name="drqp_black_tmp">
    <color rgba="0.5 0.5 0.5 0.2"/>
  </material>
  <link name="dr_qp/base_center_link">
    <visual>
      <origin rpy="1.5707963267948966 0 3.141592653589793" xyz="0 0 -0.0185"/>
      <geometry>
        <mesh filename="package://drqp_description/meshes/body-simple.stl"/>
      </geometry>
      <material name="drqp_black"/>
    </visual>
    <collision>
      <origin rpy="0 0 0" xyz="0 0 -0.0185"/>
      <geometry>
        <mesh filename="package://drqp_description/meshes/body-collision.stl"/>
      </geometry>
    </collision>
    <inertial>
      <origin rpy="0 0 0" xyz="0.001522 0.000302 0.015345"/>
      <mass value="1.522054"/>
      <inertia ixx="0.0044660000" ixy="0.0000076888" ixz="-0.0001245000" iyy="0.0084890000" iyz="0.0000050996" izz="0.0092020000"/>
    </inertial>
  </link>
  <link name="dr_qp/base_link"/>
  <!-- Robot base lowest point -->
  <joint name="base_bottom" type="fixed">
    <origin rpy="0 0 0" xyz="0 0 0.0185"/>
    <parent link="dr_qp/base_link"/>
    <child link="dr_qp/base_center_link"/>
  </joint>
  <!-- <gazebo reference=\'base_bottom\'>
    <preserveFixedJoint>true</preserveFixedJoint>
  </gazebo> -->
  <joint name="base_bottom_to_camera" type="fixed">
    <origin rpy="0 0 0" xyz="0.132 0 0"/>
    <parent link="dr_qp/base_center_link"/>
    <child link="dr_qp/camera"/>
  </joint>
  <!-- <gazebo reference=\'base_bottom_to_camera\'>
    <preserveFixedJoint>true</preserveFixedJoint>
  </gazebo> -->
  <link name="dr_qp/camera">
  </link>
  <!-- Specify some standard inertial calculations https://en.wikipedia.org/wiki/List_of_moments_of_inertia -->
  <!-- These make use of xacro\'s mathematical functionality -->
  <ros2_control name="GazeboSystem" type="system">
    <joint name="left_back_coxa">
      <command_interface name="position">
        <param name="min">-15</param>
        <param name="max">15</param>
      </command_interface>
      <state_interface name="position">
        <param name="initial_value">1.0</param>
      </state_interface>
      <state_interface name="velocity"/>
      <state_interface name="effort"/>
    </joint>
    <joint name="left_back_femur">
      <command_interface name="position">
        <param name="min">-15</param>
        <param name="max">15</param>
      </command_interface>
      <state_interface name="position">
        <param name="initial_value">1.0</param>
      </state_interface>
      <state_interface name="velocity"/>
      <state_interface name="effort"/>
    </joint>
    <joint name="left_back_tibia">
      <command_interface name="position">
        <param name="min">-15</param>
        <param name="max">15</param>
      </command_interface>
      <state_interface name="position">
        <param name="initial_value">1.0</param>
      </state_interface>
      <state_interface name="velocity"/>
      <state_interface name="effort"/>
    </joint>
    <!-- <xacro:hexjoint name="left_middle_coxa" /> -->
    <!-- <xacro:hexjoint name="left_middle_femur" /> -->
    <!-- <xacro:hexjoint name="left_middle_tibia" /> -->
    <!-- <xacro:hexjoint name="left_front_coxa" /> -->
    <!-- <xacro:hexjoint name="left_front_femur" /> -->
    <!-- <xacro:hexjoint name="left_front_tibia" /> -->
    <!-- <xacro:hexjoint name="right_front_coxa" /> -->
    <!-- <xacro:hexjoint name="right_front_femur" /> -->
    <!-- <xacro:hexjoint name="right_front_tibia" /> -->
    <!-- <xacro:hexjoint name="right_middle_coxa" /> -->
    <!-- <xacro:hexjoint name="right_middle_femur" /> -->
    <!-- <xacro:hexjoint name="right_middle_tibia" /> -->
    <!-- <xacro:hexjoint name="right_back_coxa" /> -->
    <!-- <xacro:hexjoint name="right_back_femur" /> -->
    <!-- <xacro:hexjoint name="right_back_tibia" /> -->
  </ros2_control>
  <!-- <gazebo> Fix in https://github.com/Dr-QP/Dr.QP/issues/91
        <plugin filename="libgazebo_ros2_control.so" name="gazebo_ros2_control">
          <robot_param>robot_description</robot_param>
          <robot_param_node>robot_state_publisher</robot_param_node>
          <parameters>$(find drqp_gazebo)/config/gazebo_params.yaml</parameters>
        </plugin>
    </gazebo> -->
  <joint name="dr_qp/left_front_coxa_servo" type="fixed">
    <origin rpy="0 0 0.7853981633974483" xyz="0.11692 0.06387 0"/>
    <parent link="dr_qp/base_center_link"/>
    <child link="dr_qp/left_front_coxa_servo"/>
  </joint>
  <gazebo reference="dr_qp/left_front_coxa_servo">
    <preserveFixedJoint>true</preserveFixedJoint>
  </gazebo>
  <link name="dr_qp/left_front_coxa_servo">
    <visual>
      <origin rpy="0 0 -1.5707963267948966" xyz="0 0 0"/>
      <geometry>
        <mesh filename="package://drqp_description/meshes/servo.stl"/>
      </geometry>
      <material name="drqp_black"/>
    </visual>
    <collision>
      <origin rpy="0 0 -1.5707963267948966" xyz="0 0 0"/>
      <geometry>
        <mesh filename="package://drqp_description/meshes/servo-collision.stl"/>
      </geometry>
    </collision>
    <inertial>
      <origin rpy="0 0 0" xyz="0.019066 -0.000002 0.006577"/>
      <mass value="0.02471"/>
      <inertia ixx="0.0000215400" ixy="-0.00000000122" ixz="-0.00000192741" iyy="0.00002657000" iyz="-0.00000000001" izz="0.00002925000"/>
    </inertial>
  </link>
  <joint name="dr_qp/left_front_coxa" type="revolute">
    <axis xyz="0 0 1"/>
    <limit effort="3" lower="-1.5707963267948966" upper="1.5707963267948966" velocity="3.141592653589793"/>
    <parent link="dr_qp/left_front_coxa_servo"/>
    <child link="dr_qp/left_front_coxa_f2_link_1"/>
    <!-- <dynamics damping="100" friction="0.1" /> -->
  </joint>
  <gazebo reference="dr_qp/left_front_coxa">
    <dampingFactor>0.04</dampingFactor>
    <implicitSpringDamper>true</implicitSpringDamper>
    <!-- <springStiffness>2</springStiffness> -->
    <springReference>0.01</springReference>
  </gazebo>
  <link name="dr_qp/left_front_coxa_f2_link_1">
    <visual>
      <origin rpy="0 0 1.5707963267948966" xyz="0 0 0"/>
      <geometry>
        <mesh filename="package://drqp_description/meshes/F2.stl"/>
      </geometry>
      <material name="drqp_black"/>
    </visual>
    <collision>
      <origin rpy="0 0 1.5707963267948966" xyz="0 0 0"/>
      <geometry>
        <mesh filename="package://drqp_description/meshes/F2-collision.stl"/>
      </geometry>
    </collision>
    <inertial>
      <origin rpy="0 0 0" xyz="0 0 0"/>
      <mass value="0.01"/>
      <inertia ixx="1.6666666666666668e-07" ixy="0.0" ixz="0.0" iyy="1.6666666666666668e-07" iyz="0.0" izz="1.6666666666666668e-07"/>
    </inertial>
  </link>
  <joint name="dr_qp/left_front_coxa_inner" type="fixed">
    <origin rpy="0 0 0" xyz="0.053 0 0"/>
    <parent link="dr_qp/left_front_coxa_f2_link_1"/>
    <child link="dr_qp/left_front_coxa_f2_link_2"/>
  </joint>
  <gazebo reference="dr_qp/left_front_coxa_inner">
    <preserveFixedJoint>true</preserveFixedJoint>
  </gazebo>
  <link name="dr_qp/left_front_coxa_f2_link_2">
    <visual>
      <origin rpy="0 1.5707963267948966 -1.5707963267948966" xyz="0 0 0"/>
      <geometry>
        <mesh filename="package://drqp_description/meshes/F2.stl"/>
      </geometry>
      <material name="drqp_black"/>
    </visual>
    <collision>
      <origin rpy="0 1.5707963267948966 -1.5707963267948966" xyz="0 0 0"/>
      <geometry>
        <mesh filename="package://drqp_description/meshes/F2-collision.stl"/>
      </geometry>
    </collision>
    <inertial>
      <origin rpy="0 0 0" xyz="0 0 0"/>
      <mass value="0.01"/>
      <inertia ixx="1.6666666666666668e-07" ixy="0.0" ixz="0.0" iyy="1.6666666666666668e-07" iyz="0.0" izz="1.6666666666666668e-07"/>
    </inertial>
  </link>
  <joint name="dr_qp/left_front_femur" type="revolute">
    <axis xyz="0 1 0"/>
    <limit effort="3" lower="-1.710422666954443" upper="1.5707963267948966" velocity="3.141592653589793"/>
    <origin rpy="0 0 0" xyz="0 0 0"/>
    <parent link="dr_qp/left_front_coxa_f2_link_2"/>
    <child link="dr_qp/left_front_femur_servo"/>
    <!-- <dynamics damping="100" friction="0.1" /> -->
  </joint>
  <gazebo reference="dr_qp/left_front_femur">
    <dampingFactor>0.04</dampingFactor>
    <implicitSpringDamper>true</implicitSpringDamper>
    <!-- <springStiffness>2</springStiffness> -->
    <springReference>0.01</springReference>
  </gazebo>
  <link name="dr_qp/left_front_femur_servo">
    <visual>
      <origin rpy="0 1.5707963267948966 1.5707963267948966" xyz="0 0 0"/>
      <geometry>
        <!--
          Origin is at the actuator center
          36mm - distance from actuator center to the center of the holes on the back
         -->
        <mesh filename="package://drqp_description/meshes/servo.stl"/>
      </geometry>
      <material name="drqp_black"/>
    </visual>
    <collision>
      <origin rpy="0 1.5707963267948966 1.5707963267948966" xyz="0 0 0"/>
      <geometry>
        <mesh filename="package://drqp_description/meshes/servo-collision.stl"/>
      </geometry>
    </collision>
    <inertial>
      <origin rpy="0 0 0" xyz="0.019066 -0.000002 0.006577"/>
      <mass value="0.02471"/>
      <inertia ixx="0.0000215400" ixy="-0.00000000122" ixz="-0.00000192741" iyy="0.00002657000" iyz="-0.00000000001" izz="0.00002925000"/>
    </inertial>
  </link>
  <joint name="dr_qp/left_front_femur_inner_1" type="fixed">
    <origin rpy="0 0 0" xyz="0.041499999999999995 0 0"/>
    <parent link="dr_qp/left_front_femur_servo"/>
    <child link="dr_qp/left_front_femur_link_f3"/>
  </joint>
  <gazebo reference="dr_qp/left_front_femur_inner_1">
    <preserveFixedJoint>true</preserveFixedJoint>
  </gazebo>
  <link name="dr_qp/left_front_femur_link_f3">
    <visual>
      <origin rpy="0 1.5707963267948966 1.5707963267948966" xyz="0 0 0"/>
      <geometry>
        <!--
          Origin is at the center of the flat plane
          5.5mm - distance from origin to center of the side mounting holes
         -->
        <mesh filename="package://drqp_description/meshes/F3.stl"/>
      </geometry>
      <material name="drqp_black"/>
    </visual>
    <collision>
      <origin rpy="0 1.5707963267948966 1.5707963267948966" xyz="0 0 0"/>
      <geometry>
        <mesh filename="package://drqp_description/meshes/F3-collision.stl"/>
      </geometry>
    </collision>
    <inertial>
      <origin rpy="0 0 0" xyz="0 0 0"/>
      <mass value="0.01"/>
      <inertia ixx="1.6666666666666668e-07" ixy="0.0" ixz="0.0" iyy="1.6666666666666668e-07" iyz="0.0" izz="1.6666666666666668e-07"/>
    </inertial>
  </link>
  <joint name="dr_qp/left_front_femur_inner_2" type="fixed">
    <origin rpy="0 0 0" xyz="0.023 0 -0.015"/>
    <parent link="dr_qp/left_front_femur_link_f3"/>
    <child link="dr_qp/left_front_femur_link_f1"/>
  </joint>
  <gazebo reference="dr_qp/left_front_femur_inner_2">
    <preserveFixedJoint>true</preserveFixedJoint>
  </gazebo>
  <link name="dr_qp/left_front_femur_link_f1">
    <visual>
      <origin rpy="3.141592653589793 -1.5707963267948966 1.5707963267948966" xyz="0 0 0"/>
      <geometry>
        <!--
          Origin is at the servo mount/pivot
          15.0mm - distance from origin to the center mount holes on the mount plane - x axis
          23.0mm - distance from origin to mount plane - y axis
         -->
        <mesh filename="package://drqp_description/meshes/F1.stl"/>
      </geometry>
      <material name="drqp_black"/>
    </visual>
    <collision>
      <origin rpy="3.141592653589793 -1.5707963267948966 1.5707963267948966" xyz="0 0 0"/>
      <geometry>
        <mesh filename="package://drqp_description/meshes/F1-collision.stl"/>
      </geometry>
    </collision>
    <inertial>
      <origin rpy="0 0 0" xyz="0 0 0"/>
      <mass value="0.01"/>
      <inertia ixx="1.6666666666666668e-07" ixy="0.0" ixz="0.0" iyy="1.6666666666666668e-07" iyz="0.0" izz="1.6666666666666668e-07"/>
    </inertial>
  </link>
  <joint name="dr_qp/left_front_tibia" type="revolute">
    <axis xyz="0 1 0"/>
    <limit effort="3" lower="-1.3962634015954636" upper="1.9198621771937625" velocity="3.141592653589793"/>
    <origin rpy="0 0 0" xyz="0 0 0"/>
    <parent link="dr_qp/left_front_femur_link_f1"/>
    <child link="dr_qp/left_front_tibia_servo"/>
    <!-- <dynamics damping="100" friction="0.1" /> -->
  </joint>
  <gazebo reference="dr_qp/left_front_tibia">
    <dampingFactor>0.04</dampingFactor>
    <implicitSpringDamper>true</implicitSpringDamper>
    <!-- <springStiffness>2</springStiffness> -->
    <springReference>0.01</springReference>
  </gazebo>
  <link name="dr_qp/left_front_tibia_servo">
    <visual>
      <origin rpy="0 1.5707963267948966 1.5707963267948966" xyz="0 0 0"/>
      <geometry>
        <mesh filename="package://drqp_description/meshes/servo.stl"/>
      </geometry>
      <material name="drqp_black"/>
    </visual>
    <collision>
      <origin rpy="0 1.5707963267948966 1.5707963267948966" xyz="0 0 0"/>
      <geometry>
        <mesh filename="package://drqp_description/meshes/servo-collision.stl"/>
      </geometry>
    </collision>
    <inertial>
      <origin rpy="0 0 0" xyz="0.036797 0.000054 -0.011991"/>
      <mass value="0.171825"/>
      <inertia ixx="0.0001762000" ixy="-0.0000014522" ixz="0.0001789000" iyy="0.0005158000" iyz="0.0000006181" izz="0.0003768000"/>
    </inertial>
  </link>
  <joint name="dr_qp/left_front_tibia_leg" type="fixed">
    <origin rpy="0 0 0" xyz="0.0325 0 0"/>
    <parent link="dr_qp/left_front_tibia_servo"/>
    <child link="dr_qp/left_front_tibia_leg"/>
  </joint>
  <gazebo reference="dr_qp/left_front_tibia_leg">
    <preserveFixedJoint>true</preserveFixedJoint>
  </gazebo>
  <link name="dr_qp/left_front_tibia_leg">
    <visual>
      <origin rpy="0 0 0" xyz="0 0 0"/>
      <geometry>
        <!--
          Origin is at end servo attachment, 32.5 between servo pivot and this point
         -->
        <mesh filename="package://drqp_description/meshes/Tibia.stl"/>
      </geometry>
      <material name="drqp_black"/>
    </visual>
    <collision>
      <origin rpy="0 0 0" xyz="0 0 0"/>
      <geometry>
        <mesh filename="package://drqp_description/meshes/Tibia-collision.stl"/>
      </geometry>
    </collision>
    <inertial>
      <origin rpy="0 0 0" xyz="0 0 0"/>
      <mass value="0.01"/>
      <inertia ixx="1.6666666666666668e-07" ixy="0.0" ixz="0.0" iyy="1.6666666666666668e-07" iyz="0.0" izz="1.6666666666666668e-07"/>
    </inertial>
  </link>
  <joint name="dr_qp/left_front_foot" type="fixed">
    <origin rpy="0 0 0" xyz="0.052797 0 -0.088395"/>
    <parent link="dr_qp/left_front_tibia_leg"/>
    <child link="dr_qp/left_front_foot_link"/>
  </joint>
  <gazebo reference="dr_qp/left_front_foot">
    <preserveFixedJoint>true</preserveFixedJoint>
  </gazebo>
  <link name="dr_qp/left_front_foot_link"/>
  <ros2_control name="dr_qp" type="system">
    <hardware>
      <plugin>drqp_control/a1_16_hardware_interface</plugin>
    </hardware>
    <joint name="dr_qp/left_front_coxa">
      <command_interface name="position">
        <param name="min">-1.5707963267948966</param>
        <param name="max">1.5707963267948966</param>
      </command_interface>
      <state_interface name="position"/>
    </joint>
    <joint name="dr_qp/left_front_femur">
      <command_interface name="position">
        <param name="min">-1.710422666954443</param>
        <param name="max">1.5707963267948966</param>
      </command_interface>
      <state_interface name="position"/>
    </joint>
    <joint name="dr_qp/left_front_tibia">
      <command_interface name="position">
        <param name="min">-1.3962634015954636</param>
        <param name="max">1.9198621771937625</param>
      </command_interface>
      <state_interface name="position"/>
    </joint>
  </ros2_control>
  <joint name="dr_qp/right_front_coxa_servo" type="fixed">
    <origin rpy="0 0 -0.7853981633974483" xyz="0.11692 -0.06387 0"/>
    <parent link="dr_qp/base_center_link"/>
    <child link="dr_qp/right_front_coxa_servo"/>
  </joint>
  <gazebo reference="dr_qp/right_front_coxa_servo">
    <preserveFixedJoint>true</preserveFixedJoint>
  </gazebo>
  <link name="dr_qp/right_front_coxa_servo">
    <visual>
      <origin rpy="0 0 -1.5707963267948966" xyz="0 0 0"/>
      <geometry>
        <mesh filename="package://drqp_description/meshes/servo.stl"/>
      </geometry>
      <material name="drqp_black"/>
    </visual>
    <collision>
      <origin rpy="0 0 -1.5707963267948966" xyz="0 0 0"/>
      <geometry>
        <mesh filename="package://drqp_description/meshes/servo-collision.stl"/>
      </geometry>
    </collision>
    <inertial>
      <origin rpy="0 0 0" xyz="0.019066 -0.000002 0.006577"/>
      <mass value="0.02471"/>
      <inertia ixx="0.0000215400" ixy="-0.00000000122" ixz="-0.00000192741" iyy="0.00002657000" iyz="-0.00000000001" izz="0.00002925000"/>
    </inertial>
  </link>
  <joint name="dr_qp/right_front_coxa" type="revolute">
    <axis xyz="0 0 1"/>
    <limit effort="3" lower="-1.5707963267948966" upper="1.5707963267948966" velocity="3.141592653589793"/>
    <parent link="dr_qp/right_front_coxa_servo"/>
    <child link="dr_qp/right_front_coxa_f2_link_1"/>
    <!-- <dynamics damping="100" friction="0.1" /> -->
  </joint>
  <gazebo reference="dr_qp/right_front_coxa">
    <dampingFactor>0.04</dampingFactor>
    <implicitSpringDamper>true</implicitSpringDamper>
    <!-- <springStiffness>2</springStiffness> -->
    <springReference>0.01</springReference>
  </gazebo>
  <link name="dr_qp/right_front_coxa_f2_link_1">
    <visual>
      <origin rpy="0 0 1.5707963267948966" xyz="0 0 0"/>
      <geometry>
        <mesh filename="package://drqp_description/meshes/F2.stl"/>
      </geometry>
      <material name="drqp_black"/>
    </visual>
    <collision>
      <origin rpy="0 0 1.5707963267948966" xyz="0 0 0"/>
      <geometry>
        <mesh filename="package://drqp_description/meshes/F2-collision.stl"/>
      </geometry>
    </collision>
    <inertial>
      <origin rpy="0 0 0" xyz="0 0 0"/>
      <mass value="0.01"/>
      <inertia ixx="1.6666666666666668e-07" ixy="0.0" ixz="0.0" iyy="1.6666666666666668e-07" iyz="0.0" izz="1.6666666666666668e-07"/>
    </inertial>
  </link>
  <joint name="dr_qp/right_front_coxa_inner" type="fixed">
    <origin rpy="0 0 0" xyz="0.053 0 0"/>
    <parent link="dr_qp/right_front_coxa_f2_link_1"/>
    <child link="dr_qp/right_front_coxa_f2_link_2"/>
  </joint>
  <gazebo reference="dr_qp/right_front_coxa_inner">
    <preserveFixedJoint>true</preserveFixedJoint>
  </gazebo>
  <link name="dr_qp/right_front_coxa_f2_link_2">
    <visual>
      <origin rpy="0 1.5707963267948966 -1.5707963267948966" xyz="0 0 0"/>
      <geometry>
        <mesh filename="package://drqp_description/meshes/F2.stl"/>
      </geometry>
      <material name="drqp_black"/>
    </visual>
    <collision>
      <origin rpy="0 1.5707963267948966 -1.5707963267948966" xyz="0 0 0"/>
      <geometry>
        <mesh filename="package://drqp_description/meshes/F2-collision.stl"/>
      </geometry>
    </collision>
    <inertial>
      <origin rpy="0 0 0" xyz="0 0 0"/>
      <mass value="0.01"/>
      <inertia ixx="1.6666666666666668e-07" ixy="0.0" ixz="0.0" iyy="1.6666666666666668e-07" iyz="0.0" izz="1.6666666666666668e-07"/>
    </inertial>
  </link>
  <joint name="dr_qp/right_front_femur" type="revolute">
    <axis xyz="0 1 0"/>
    <limit effort="3" lower="-1.710422666954443" upper="1.5707963267948966" velocity="3.141592653589793"/>
    <origin rpy="0 0 0" xyz="0 0 0"/>
    <parent link="dr_qp/right_front_coxa_f2_link_2"/>
    <child link="dr_qp/right_front_femur_servo"/>
    <!-- <dynamics damping="100" friction="0.1" /> -->
  </joint>
  <gazebo reference="dr_qp/right_front_femur">
    <dampingFactor>0.04</dampingFactor>
    <implicitSpringDamper>true</implicitSpringDamper>
    <!-- <springStiffness>2</springStiffness> -->
    <springReference>0.01</springReference>
  </gazebo>
  <link name="dr_qp/right_front_femur_servo">
    <visual>
      <origin rpy="0 1.5707963267948966 1.5707963267948966" xyz="0 0 0"/>
      <geometry>
        <!--
          Origin is at the actuator center
          36mm - distance from actuator center to the center of the holes on the back
         -->
        <mesh filename="package://drqp_description/meshes/servo.stl"/>
      </geometry>
      <material name="drqp_black"/>
    </visual>
    <collision>
      <origin rpy="0 1.5707963267948966 1.5707963267948966" xyz="0 0 0"/>
      <geometry>
        <mesh filename="package://drqp_description/meshes/servo-collision.stl"/>
      </geometry>
    </collision>
    <inertial>
      <origin rpy="0 0 0" xyz="0.019066 -0.000002 0.006577"/>
      <mass value="0.02471"/>
      <inertia ixx="0.0000215400" ixy="-0.00000000122" ixz="-0.00000192741" iyy="0.00002657000" iyz="-0.00000000001" izz="0.00002925000"/>
    </inertial>
  </link>
  <joint name="dr_qp/right_front_femur_inner_1" type="fixed">
    <origin rpy="0 0 0" xyz="0.041499999999999995 0 0"/>
    <parent link="dr_qp/right_front_femur_servo"/>
    <child link="dr_qp/right_front_femur_link_f3"/>
  </joint>
  <gazebo reference="dr_qp/right_front_femur_inner_1">
    <preserveFixedJoint>true</preserveFixedJoint>
  </gazebo>
  <link name="dr_qp/right_front_femur_link_f3">
    <visual>
      <origin rpy="0 1.5707963267948966 1.5707963267948966" xyz="0 0 0"/>
      <geometry>
        <!--
          Origin is at the center of the flat plane
          5.5mm - distance from origin to center of the side mounting holes
         -->
        <mesh filename="package://drqp_description/meshes/F3.stl"/>
      </geometry>
      <material name="drqp_black"/>
    </visual>
    <collision>
      <origin rpy="0 1.5707963267948966 1.5707963267948966" xyz="0 0 0"/>
      <geometry>
        <mesh filename="package://drqp_description/meshes/F3-collision.stl"/>
      </geometry>
    </collision>
    <inertial>
      <origin rpy="0 0 0" xyz="0 0 0"/>
      <mass value="0.01"/>
      <inertia ixx="1.6666666666666668e-07" ixy="0.0" ixz="0.0" iyy="1.6666666666666668e-07" iyz="0.0" izz="1.6666666666666668e-07"/>
    </inertial>
  </link>
  <joint name="dr_qp/right_front_femur_inner_2" type="fixed">
    <origin rpy="0 0 0" xyz="0.023 0 -0.015"/>
    <parent link="dr_qp/right_front_femur_link_f3"/>
    <child link="dr_qp/right_front_femur_link_f1"/>
  </joint>
  <gazebo reference="dr_qp/right_front_femur_inner_2">
    <preserveFixedJoint>true</preserveFixedJoint>
  </gazebo>
  <link name="dr_qp/right_front_femur_link_f1">
    <visual>
      <origin rpy="3.141592653589793 -1.5707963267948966 1.5707963267948966" xyz="0 0 0"/>
      <geometry>
        <!--
          Origin is at the servo mount/pivot
          15.0mm - distance from origin to the center mount holes on the mount plane - x axis
          23.0mm - distance from origin to mount plane - y axis
         -->
        <mesh filename="package://drqp_description/meshes/F1.stl"/>
      </geometry>
      <material name="drqp_black"/>
    </visual>
    <collision>
      <origin rpy="3.141592653589793 -1.5707963267948966 1.5707963267948966" xyz="0 0 0"/>
      <geometry>
        <mesh filename="package://drqp_description/meshes/F1-collision.stl"/>
      </geometry>
    </collision>
    <inertial>
      <origin rpy="0 0 0" xyz="0 0 0"/>
      <mass value="0.01"/>
      <inertia ixx="1.6666666666666668e-07" ixy="0.0" ixz="0.0" iyy="1.6666666666666668e-07" iyz="0.0" izz="1.6666666666666668e-07"/>
    </inertial>
  </link>
  <joint name="dr_qp/right_front_tibia" type="revolute">
    <axis xyz="0 1 0"/>
    <limit effort="3" lower="-1.3962634015954636" upper="1.9198621771937625" velocity="3.141592653589793"/>
    <origin rpy="0 0 0" xyz="0 0 0"/>
    <parent link="dr_qp/right_front_femur_link_f1"/>
    <child link="dr_qp/right_front_tibia_servo"/>
    <!-- <dynamics damping="100" friction="0.1" /> -->
  </joint>
  <gazebo reference="dr_qp/right_front_tibia">
    <dampingFactor>0.04</dampingFactor>
    <implicitSpringDamper>true</implicitSpringDamper>
    <!-- <springStiffness>2</springStiffness> -->
    <springReference>0.01</springReference>
  </gazebo>
  <link name="dr_qp/right_front_tibia_servo">
    <visual>
      <origin rpy="0 1.5707963267948966 1.5707963267948966" xyz="0 0 0"/>
      <geometry>
        <mesh filename="package://drqp_description/meshes/servo.stl"/>
      </geometry>
      <material name="drqp_black"/>
    </visual>
    <collision>
      <origin rpy="0 1.5707963267948966 1.5707963267948966" xyz="0 0 0"/>
      <geometry>
        <mesh filename="package://drqp_description/meshes/servo-collision.stl"/>
      </geometry>
    </collision>
    <inertial>
      <origin rpy="0 0 0" xyz="0.036797 0.000054 -0.011991"/>
      <mass value="0.171825"/>
      <inertia ixx="0.0001762000" ixy="-0.0000014522" ixz="0.0001789000" iyy="0.0005158000" iyz="0.0000006181" izz="0.0003768000"/>
    </inertial>
  </link>
  <joint name="dr_qp/right_front_tibia_leg" type="fixed">
    <origin rpy="0 0 0" xyz="0.0325 0 0"/>
    <parent link="dr_qp/right_front_tibia_servo"/>
    <child link="dr_qp/right_front_tibia_leg"/>
  </joint>
  <gazebo reference="dr_qp/right_front_tibia_leg">
    <preserveFixedJoint>true</preserveFixedJoint>
  </gazebo>
  <link name="dr_qp/right_front_tibia_leg">
    <visual>
      <origin rpy="0 0 0" xyz="0 0 0"/>
      <geometry>
        <!--
          Origin is at end servo attachment, 32.5 between servo pivot and this point
         -->
        <mesh filename="package://drqp_description/meshes/Tibia.stl"/>
      </geometry>
      <material name="drqp_black"/>
    </visual>
    <collision>
      <origin rpy="0 0 0" xyz="0 0 0"/>
      <geometry>
        <mesh filename="package://drqp_description/meshes/Tibia-collision.stl"/>
      </geometry>
    </collision>
    <inertial>
      <origin rpy="0 0 0" xyz="0 0 0"/>
      <mass value="0.01"/>
      <inertia ixx="1.6666666666666668e-07" ixy="0.0" ixz="0.0" iyy="1.6666666666666668e-07" iyz="0.0" izz="1.6666666666666668e-07"/>
    </inertial>
  </link>
  <joint name="dr_qp/right_front_foot" type="fixed">
    <origin rpy="0 0 0" xyz="0.052797 0 -0.088395"/>
    <parent link="dr_qp/right_front_tibia_leg"/>
    <child link="dr_qp/right_front_foot_link"/>
  </joint>
  <gazebo reference="dr_qp/right_front_foot">
    <preserveFixedJoint>true</preserveFixedJoint>
  </gazebo>
  <link name="dr_qp/right_front_foot_link"/>
  <ros2_control name="dr_qp" type="system">
    <hardware>
      <plugin>drqp_control/a1_16_hardware_interface</plugin>
    </hardware>
    <joint name="dr_qp/right_front_coxa">
      <command_interface name="position">
        <param name="min">-1.5707963267948966</param>
        <param name="max">1.5707963267948966</param>
      </command_interface>
      <state_interface name="position"/>
    </joint>
    <joint name="dr_qp/right_front_femur">
      <command_interface name="position">
        <param name="min">-1.710422666954443</param>
        <param name="max">1.5707963267948966</param>
      </command_interface>
      <state_interface name="position"/>
    </joint>
    <joint name="dr_qp/right_front_tibia">
      <command_interface name="position">
        <param name="min">-1.3962634015954636</param>
        <param name="max">1.9198621771937625</param>
      </command_interface>
      <state_interface name="position"/>
    </joint>
  </ros2_control>
  <joint name="dr_qp/left_middle_coxa_servo" type="fixed">
    <origin rpy="0 0 1.5707963267948966" xyz="0 0.103 0"/>
    <parent link="dr_qp/base_center_link"/>
    <child link="dr_qp/left_middle_coxa_servo"/>
  </joint>
  <gazebo reference="dr_qp/left_middle_coxa_servo">
    <preserveFixedJoint>true</preserveFixedJoint>
  </gazebo>
  <link name="dr_qp/left_middle_coxa_servo">
    <visual>
      <origin rpy="0 0 -1.5707963267948966" xyz="0 0 0"/>
      <geometry>
        <mesh filename="package://drqp_description/meshes/servo.stl"/>
      </geometry>
      <material name="drqp_black"/>
    </visual>
    <collision>
      <origin rpy="0 0 -1.5707963267948966" xyz="0 0 0"/>
      <geometry>
        <mesh filename="package://drqp_description/meshes/servo-collision.stl"/>
      </geometry>
    </collision>
    <inertial>
      <origin rpy="0 0 0" xyz="0.019066 -0.000002 0.006577"/>
      <mass value="0.02471"/>
      <inertia ixx="0.0000215400" ixy="-0.00000000122" ixz="-0.00000192741" iyy="0.00002657000" iyz="-0.00000000001" izz="0.00002925000"/>
    </inertial>
  </link>
  <joint name="dr_qp/left_middle_coxa" type="revolute">
    <axis xyz="0 0 1"/>
    <limit effort="3" lower="-1.5707963267948966" upper="1.5707963267948966" velocity="3.141592653589793"/>
    <parent link="dr_qp/left_middle_coxa_servo"/>
    <child link="dr_qp/left_middle_coxa_f2_link_1"/>
    <!-- <dynamics damping="100" friction="0.1" /> -->
  </joint>
  <gazebo reference="dr_qp/left_middle_coxa">
    <dampingFactor>0.04</dampingFactor>
    <implicitSpringDamper>true</implicitSpringDamper>
    <!-- <springStiffness>2</springStiffness> -->
    <springReference>0.01</springReference>
  </gazebo>
  <link name="dr_qp/left_middle_coxa_f2_link_1">
    <visual>
      <origin rpy="0 0 1.5707963267948966" xyz="0 0 0"/>
      <geometry>
        <mesh filename="package://drqp_description/meshes/F2.stl"/>
      </geometry>
      <material name="drqp_black"/>
    </visual>
    <collision>
      <origin rpy="0 0 1.5707963267948966" xyz="0 0 0"/>
      <geometry>
        <mesh filename="package://drqp_description/meshes/F2-collision.stl"/>
      </geometry>
    </collision>
    <inertial>
      <origin rpy="0 0 0" xyz="0 0 0"/>
      <mass value="0.01"/>
      <inertia ixx="1.6666666666666668e-07" ixy="0.0" ixz="0.0" iyy="1.6666666666666668e-07" iyz="0.0" izz="1.6666666666666668e-07"/>
    </inertial>
  </link>
  <joint name="dr_qp/left_middle_coxa_inner" type="fixed">
    <origin rpy="0 0 0" xyz="0.053 0 0"/>
    <parent link="dr_qp/left_middle_coxa_f2_link_1"/>
    <child link="dr_qp/left_middle_coxa_f2_link_2"/>
  </joint>
  <gazebo reference="dr_qp/left_middle_coxa_inner">
    <preserveFixedJoint>true</preserveFixedJoint>
  </gazebo>
  <link name="dr_qp/left_middle_coxa_f2_link_2">
    <visual>
      <origin rpy="0 1.5707963267948966 -1.5707963267948966" xyz="0 0 0"/>
      <geometry>
        <mesh filename="package://drqp_description/meshes/F2.stl"/>
      </geometry>
      <material name="drqp_black"/>
    </visual>
    <collision>
      <origin rpy="0 1.5707963267948966 -1.5707963267948966" xyz="0 0 0"/>
      <geometry>
        <mesh filename="package://drqp_description/meshes/F2-collision.stl"/>
      </geometry>
    </collision>
    <inertial>
      <origin rpy="0 0 0" xyz="0 0 0"/>
      <mass value="0.01"/>
      <inertia ixx="1.6666666666666668e-07" ixy="0.0" ixz="0.0" iyy="1.6666666666666668e-07" iyz="0.0" izz="1.6666666666666668e-07"/>
    </inertial>
  </link>
  <joint name="dr_qp/left_middle_femur" type="revolute">
    <axis xyz="0 1 0"/>
    <limit effort="3" lower="-1.710422666954443" upper="1.5707963267948966" velocity="3.141592653589793"/>
    <origin rpy="0 0 0" xyz="0 0 0"/>
    <parent link="dr_qp/left_middle_coxa_f2_link_2"/>
    <child link="dr_qp/left_middle_femur_servo"/>
    <!-- <dynamics damping="100" friction="0.1" /> -->
  </joint>
  <gazebo reference="dr_qp/left_middle_femur">
    <dampingFactor>0.04</dampingFactor>
    <implicitSpringDamper>true</implicitSpringDamper>
    <!-- <springStiffness>2</springStiffness> -->
    <springReference>0.01</springReference>
  </gazebo>
  <link name="dr_qp/left_middle_femur_servo">
    <visual>
      <origin rpy="0 1.5707963267948966 1.5707963267948966" xyz="0 0 0"/>
      <geometry>
        <!--
          Origin is at the actuator center
          36mm - distance from actuator center to the center of the holes on the back
         -->
        <mesh filename="package://drqp_description/meshes/servo.stl"/>
      </geometry>
      <material name="drqp_black"/>
    </visual>
    <collision>
      <origin rpy="0 1.5707963267948966 1.5707963267948966" xyz="0 0 0"/>
      <geometry>
        <mesh filename="package://drqp_description/meshes/servo-collision.stl"/>
      </geometry>
    </collision>
    <inertial>
      <origin rpy="0 0 0" xyz="0.019066 -0.000002 0.006577"/>
      <mass value="0.02471"/>
      <inertia ixx="0.0000215400" ixy="-0.00000000122" ixz="-0.00000192741" iyy="0.00002657000" iyz="-0.00000000001" izz="0.00002925000"/>
    </inertial>
  </link>
  <joint name="dr_qp/left_middle_femur_inner_1" type="fixed">
    <origin rpy="0 0 0" xyz="0.041499999999999995 0 0"/>
    <parent link="dr_qp/left_middle_femur_servo"/>
    <child link="dr_qp/left_middle_femur_link_f3"/>
  </joint>
  <gazebo reference="dr_qp/left_middle_femur_inner_1">
    <preserveFixedJoint>true</preserveFixedJoint>
  </gazebo>
  <link name="dr_qp/left_middle_femur_link_f3">
    <visual>
      <origin rpy="0 1.5707963267948966 1.5707963267948966" xyz="0 0 0"/>
      <geometry>
        <!--
          Origin is at the center of the flat plane
          5.5mm - distance from origin to center of the side mounting holes
         -->
        <mesh filename="package://drqp_description/meshes/F3.stl"/>
      </geometry>
      <material name="drqp_black"/>
    </visual>
    <collision>
      <origin rpy="0 1.5707963267948966 1.5707963267948966" xyz="0 0 0"/>
      <geometry>
        <mesh filename="package://drqp_description/meshes/F3-collision.stl"/>
      </geometry>
    </collision>
    <inertial>
      <origin rpy="0 0 0" xyz="0 0 0"/>
      <mass value="0.01"/>
      <inertia ixx="1.6666666666666668e-07" ixy="0.0" ixz="0.0" iyy="1.6666666666666668e-07" iyz="0.0" izz="1.6666666666666668e-07"/>
    </inertial>
  </link>
  <joint name="dr_qp/left_middle_femur_inner_2" type="fixed">
    <origin rpy="0 0 0" xyz="0.023 0 -0.015"/>
    <parent link="dr_qp/left_middle_femur_link_f3"/>
    <child link="dr_qp/left_middle_femur_link_f1"/>
  </joint>
  <gazebo reference="dr_qp/left_middle_femur_inner_2">
    <preserveFixedJoint>true</preserveFixedJoint>
  </gazebo>
  <link name="dr_qp/left_middle_femur_link_f1">
    <visual>
      <origin rpy="3.141592653589793 -1.5707963267948966 1.5707963267948966" xyz="0 0 0"/>
      <geometry>
        <!--
          Origin is at the servo mount/pivot
          15.0mm - distance from origin to the center mount holes on the mount plane - x axis
          23.0mm - distance from origin to mount plane - y axis
         -->
        <mesh filename="package://drqp_description/meshes/F1.stl"/>
      </geometry>
      <material name="drqp_black"/>
    </visual>
    <collision>
      <origin rpy="3.141592653589793 -1.5707963267948966 1.5707963267948966" xyz="0 0 0"/>
      <geometry>
        <mesh filename="package://drqp_description/meshes/F1-collision.stl"/>
      </geometry>
    </collision>
    <inertial>
      <origin rpy="0 0 0" xyz="0 0 0"/>
      <mass value="0.01"/>
      <inertia ixx="1.6666666666666668e-07" ixy="0.0" ixz="0.0" iyy="1.6666666666666668e-07" iyz="0.0" izz="1.6666666666666668e-07"/>
    </inertial>
  </link>
  <joint name="dr_qp/left_middle_tibia" type="revolute">
    <axis xyz="0 1 0"/>
    <limit effort="3" lower="-1.3962634015954636" upper="1.9198621771937625" velocity="3.141592653589793"/>
    <origin rpy="0 0 0" xyz="0 0 0"/>
    <parent link="dr_qp/left_middle_femur_link_f1"/>
    <child link="dr_qp/left_middle_tibia_servo"/>
    <!-- <dynamics damping="100" friction="0.1" /> -->
  </joint>
  <gazebo reference="dr_qp/left_middle_tibia">
    <dampingFactor>0.04</dampingFactor>
    <implicitSpringDamper>true</implicitSpringDamper>
    <!-- <springStiffness>2</springStiffness> -->
    <springReference>0.01</springReference>
  </gazebo>
  <link name="dr_qp/left_middle_tibia_servo">
    <visual>
      <origin rpy="0 1.5707963267948966 1.5707963267948966" xyz="0 0 0"/>
      <geometry>
        <mesh filename="package://drqp_description/meshes/servo.stl"/>
      </geometry>
      <material name="drqp_black"/>
    </visual>
    <collision>
      <origin rpy="0 1.5707963267948966 1.5707963267948966" xyz="0 0 0"/>
      <geometry>
        <mesh filename="package://drqp_description/meshes/servo-collision.stl"/>
      </geometry>
    </collision>
    <inertial>
      <origin rpy="0 0 0" xyz="0.036797 0.000054 -0.011991"/>
      <mass value="0.171825"/>
      <inertia ixx="0.0001762000" ixy="-0.0000014522" ixz="0.0001789000" iyy="0.0005158000" iyz="0.0000006181" izz="0.0003768000"/>
    </inertial>
  </link>
  <joint name="dr_qp/left_middle_tibia_leg" type="fixed">
    <origin rpy="0 0 0" xyz="0.0325 0 0"/>
    <parent link="dr_qp/left_middle_tibia_servo"/>
    <child link="dr_qp/left_middle_tibia_leg"/>
  </joint>
  <gazebo reference="dr_qp/left_middle_tibia_leg">
    <preserveFixedJoint>true</preserveFixedJoint>
  </gazebo>
  <link name="dr_qp/left_middle_tibia_leg">
    <visual>
      <origin rpy="0 0 0" xyz="0 0 0"/>
      <geometry>
        <!--
          Origin is at end servo attachment, 32.5 between servo pivot and this point
         -->
        <mesh filename="package://drqp_description/meshes/Tibia.stl"/>
      </geometry>
      <material name="drqp_black"/>
    </visual>
    <collision>
      <origin rpy="0 0 0" xyz="0 0 0"/>
      <geometry>
        <mesh filename="package://drqp_description/meshes/Tibia-collision.stl"/>
      </geometry>
    </collision>
    <inertial>
      <origin rpy="0 0 0" xyz="0 0 0"/>
      <mass value="0.01"/>
      <inertia ixx="1.6666666666666668e-07" ixy="0.0" ixz="0.0" iyy="1.6666666666666668e-07" iyz="0.0" izz="1.6666666666666668e-07"/>
    </inertial>
  </link>
  <joint name="dr_qp/left_middle_foot" type="fixed">
    <origin rpy="0 0 0" xyz="0.052797 0 -0.088395"/>
    <parent link="dr_qp/left_middle_tibia_leg"/>
    <child link="dr_qp/left_middle_foot_link"/>
  </joint>
  <gazebo reference="dr_qp/left_middle_foot">
    <preserveFixedJoint>true</preserveFixedJoint>
  </gazebo>
  <link name="dr_qp/left_middle_foot_link"/>
  <ros2_control name="dr_qp" type="system">
    <hardware>
      <plugin>drqp_control/a1_16_hardware_interface</plugin>
    </hardware>
    <joint name="dr_qp/left_middle_coxa">
      <command_interface name="position">
        <param name="min">-1.5707963267948966</param>
        <param name="max">1.5707963267948966</param>
      </command_interface>
      <state_interface name="position"/>
    </joint>
    <joint name="dr_qp/left_middle_femur">
      <command_interface name="position">
        <param name="min">-1.710422666954443</param>
        <param name="max">1.5707963267948966</param>
      </command_interface>
      <state_interface name="position"/>
    </joint>
    <joint name="dr_qp/left_middle_tibia">
      <command_interface name="position">
        <param name="min">-1.3962634015954636</param>
        <param name="max">1.9198621771937625</param>
      </command_interface>
      <state_interface name="position"/>
    </joint>
  </ros2_control>
  <joint name="dr_qp/right_middle_coxa_servo" type="fixed">
    <origin rpy="0 0 -1.5707963267948966" xyz="0 -0.103 0"/>
    <parent link="dr_qp/base_center_link"/>
    <child link="dr_qp/right_middle_coxa_servo"/>
  </joint>
  <gazebo reference="dr_qp/right_middle_coxa_servo">
    <preserveFixedJoint>true</preserveFixedJoint>
  </gazebo>
  <link name="dr_qp/right_middle_coxa_servo">
    <visual>
      <origin rpy="0 0 -1.5707963267948966" xyz="0 0 0"/>
      <geometry>
        <mesh filename="package://drqp_description/meshes/servo.stl"/>
      </geometry>
      <material name="drqp_black"/>
    </visual>
    <collision>
      <origin rpy="0 0 -1.5707963267948966" xyz="0 0 0"/>
      <geometry>
        <mesh filename="package://drqp_description/meshes/servo-collision.stl"/>
      </geometry>
    </collision>
    <inertial>
      <origin rpy="0 0 0" xyz="0.019066 -0.000002 0.006577"/>
      <mass value="0.02471"/>
      <inertia ixx="0.0000215400" ixy="-0.00000000122" ixz="-0.00000192741" iyy="0.00002657000" iyz="-0.00000000001" izz="0.00002925000"/>
    </inertial>
  </link>
  <joint name="dr_qp/right_middle_coxa" type="revolute">
    <axis xyz="0 0 1"/>
    <limit effort="3" lower="-1.5707963267948966" upper="1.5707963267948966" velocity="3.141592653589793"/>
    <parent link="dr_qp/right_middle_coxa_servo"/>
    <child link="dr_qp/right_middle_coxa_f2_link_1"/>
    <!-- <dynamics damping="100" friction="0.1" /> -->
  </joint>
  <gazebo reference="dr_qp/right_middle_coxa">
    <dampingFactor>0.04</dampingFactor>
    <implicitSpringDamper>true</implicitSpringDamper>
    <!-- <springStiffness>2</springStiffness> -->
    <springReference>0.01</springReference>
  </gazebo>
  <link name="dr_qp/right_middle_coxa_f2_link_1">
    <visual>
      <origin rpy="0 0 1.5707963267948966" xyz="0 0 0"/>
      <geometry>
        <mesh filename="package://drqp_description/meshes/F2.stl"/>
      </geometry>
      <material name="drqp_black"/>
    </visual>
    <collision>
      <origin rpy="0 0 1.5707963267948966" xyz="0 0 0"/>
      <geometry>
        <mesh filename="package://drqp_description/meshes/F2-collision.stl"/>
      </geometry>
    </collision>
    <inertial>
      <origin rpy="0 0 0" xyz="0 0 0"/>
      <mass value="0.01"/>
      <inertia ixx="1.6666666666666668e-07" ixy="0.0" ixz="0.0" iyy="1.6666666666666668e-07" iyz="0.0" izz="1.6666666666666668e-07"/>
    </inertial>
  </link>
  <joint name="dr_qp/right_middle_coxa_inner" type="fixed">
    <origin rpy="0 0 0" xyz="0.053 0 0"/>
    <parent link="dr_qp/right_middle_coxa_f2_link_1"/>
    <child link="dr_qp/right_middle_coxa_f2_link_2"/>
  </joint>
  <gazebo reference="dr_qp/right_middle_coxa_inner">
    <preserveFixedJoint>true</preserveFixedJoint>
  </gazebo>
  <link name="dr_qp/right_middle_coxa_f2_link_2">
    <visual>
      <origin rpy="0 1.5707963267948966 -1.5707963267948966" xyz="0 0 0"/>
      <geometry>
        <mesh filename="package://drqp_description/meshes/F2.stl"/>
      </geometry>
      <material name="drqp_black"/>
    </visual>
    <collision>
      <origin rpy="0 1.5707963267948966 -1.5707963267948966" xyz="0 0 0"/>
      <geometry>
        <mesh filename="package://drqp_description/meshes/F2-collision.stl"/>
      </geometry>
    </collision>
    <inertial>
      <origin rpy="0 0 0" xyz="0 0 0"/>
      <mass value="0.01"/>
      <inertia ixx="1.6666666666666668e-07" ixy="0.0" ixz="0.0" iyy="1.6666666666666668e-07" iyz="0.0" izz="1.6666666666666668e-07"/>
    </inertial>
  </link>
  <joint name="dr_qp/right_middle_femur" type="revolute">
    <axis xyz="0 1 0"/>
    <limit effort="3" lower="-1.710422666954443" upper="1.5707963267948966" velocity="3.141592653589793"/>
    <origin rpy="0 0 0" xyz="0 0 0"/>
    <parent link="dr_qp/right_middle_coxa_f2_link_2"/>
    <child link="dr_qp/right_middle_femur_servo"/>
    <!-- <dynamics damping="100" friction="0.1" /> -->
  </joint>
  <gazebo reference="dr_qp/right_middle_femur">
    <dampingFactor>0.04</dampingFactor>
    <implicitSpringDamper>true</implicitSpringDamper>
    <!-- <springStiffness>2</springStiffness> -->
    <springReference>0.01</springReference>
  </gazebo>
  <link name="dr_qp/right_middle_femur_servo">
    <visual>
      <origin rpy="0 1.5707963267948966 1.5707963267948966" xyz="0 0 0"/>
      <geometry>
        <!--
          Origin is at the actuator center
          36mm - distance from actuator center to the center of the holes on the back
         -->
        <mesh filename="package://drqp_description/meshes/servo.stl"/>
      </geometry>
      <material name="drqp_black"/>
    </visual>
    <collision>
      <origin rpy="0 1.5707963267948966 1.5707963267948966" xyz="0 0 0"/>
      <geometry>
        <mesh filename="package://drqp_description/meshes/servo-collision.stl"/>
      </geometry>
    </collision>
    <inertial>
      <origin rpy="0 0 0" xyz="0.019066 -0.000002 0.006577"/>
      <mass value="0.02471"/>
      <inertia ixx="0.0000215400" ixy="-0.00000000122" ixz="-0.00000192741" iyy="0.00002657000" iyz="-0.00000000001" izz="0.00002925000"/>
    </inertial>
  </link>
  <joint name="dr_qp/right_middle_femur_inner_1" type="fixed">
    <origin rpy="0 0 0" xyz="0.041499999999999995 0 0"/>
    <parent link="dr_qp/right_middle_femur_servo"/>
    <child link="dr_qp/right_middle_femur_link_f3"/>
  </joint>
  <gazebo reference="dr_qp/right_middle_femur_inner_1">
    <preserveFixedJoint>true</preserveFixedJoint>
  </gazebo>
  <link name="dr_qp/right_middle_femur_link_f3">
    <visual>
      <origin rpy="0 1.5707963267948966 1.5707963267948966" xyz="0 0 0"/>
      <geometry>
        <!--
          Origin is at the center of the flat plane
          5.5mm - distance from origin to center of the side mounting holes
         -->
        <mesh filename="package://drqp_description/meshes/F3.stl"/>
      </geometry>
      <material name="drqp_black"/>
    </visual>
    <collision>
      <origin rpy="0 1.5707963267948966 1.5707963267948966" xyz="0 0 0"/>
      <geometry>
        <mesh filename="package://drqp_description/meshes/F3-collision.stl"/>
      </geometry>
    </collision>
    <inertial>
      <origin rpy="0 0 0" xyz="0 0 0"/>
      <mass value="0.01"/>
      <inertia ixx="1.6666666666666668e-07" ixy="0.0" ixz="0.0" iyy="1.6666666666666668e-07" iyz="0.0" izz="1.6666666666666668e-07"/>
    </inertial>
  </link>
  <joint name="dr_qp/right_middle_femur_inner_2" type="fixed">
    <origin rpy="0 0 0" xyz="0.023 0 -0.015"/>
    <parent link="dr_qp/right_middle_femur_link_f3"/>
    <child link="dr_qp/right_middle_femur_link_f1"/>
  </joint>
  <gazebo reference="dr_qp/right_middle_femur_inner_2">
    <preserveFixedJoint>true</preserveFixedJoint>
  </gazebo>
  <link name="dr_qp/right_middle_femur_link_f1">
    <visual>
      <origin rpy="3.141592653589793 -1.5707963267948966 1.5707963267948966" xyz="0 0 0"/>
      <geometry>
        <!--
          Origin is at the servo mount/pivot
          15.0mm - distance from origin to the center mount holes on the mount plane - x axis
          23.0mm - distance from origin to mount plane - y axis
         -->
        <mesh filename="package://drqp_description/meshes/F1.stl"/>
      </geometry>
      <material name="drqp_black"/>
    </visual>
    <collision>
      <origin rpy="3.141592653589793 -1.5707963267948966 1.5707963267948966" xyz="0 0 0"/>
      <geometry>
        <mesh filename="package://drqp_description/meshes/F1-collision.stl"/>
      </geometry>
    </collision>
    <inertial>
      <origin rpy="0 0 0" xyz="0 0 0"/>
      <mass value="0.01"/>
      <inertia ixx="1.6666666666666668e-07" ixy="0.0" ixz="0.0" iyy="1.6666666666666668e-07" iyz="0.0" izz="1.6666666666666668e-07"/>
    </inertial>
  </link>
  <joint name="dr_qp/right_middle_tibia" type="revolute">
    <axis xyz="0 1 0"/>
    <limit effort="3" lower="-1.3962634015954636" upper="1.9198621771937625" velocity="3.141592653589793"/>
    <origin rpy="0 0 0" xyz="0 0 0"/>
    <parent link="dr_qp/right_middle_femur_link_f1"/>
    <child link="dr_qp/right_middle_tibia_servo"/>
    <!-- <dynamics damping="100" friction="0.1" /> -->
  </joint>
  <gazebo reference="dr_qp/right_middle_tibia">
    <dampingFactor>0.04</dampingFactor>
    <implicitSpringDamper>true</implicitSpringDamper>
    <!-- <springStiffness>2</springStiffness> -->
    <springReference>0.01</springReference>
  </gazebo>
  <link name="dr_qp/right_middle_tibia_servo">
    <visual>
      <origin rpy="0 1.5707963267948966 1.5707963267948966" xyz="0 0 0"/>
      <geometry>
        <mesh filename="package://drqp_description/meshes/servo.stl"/>
      </geometry>
      <material name="drqp_black"/>
    </visual>
    <collision>
      <origin rpy="0 1.5707963267948966 1.5707963267948966" xyz="0 0 0"/>
      <geometry>
        <mesh filename="package://drqp_description/meshes/servo-collision.stl"/>
      </geometry>
    </collision>
    <inertial>
      <origin rpy="0 0 0" xyz="0.036797 0.000054 -0.011991"/>
      <mass value="0.171825"/>
      <inertia ixx="0.0001762000" ixy="-0.0000014522" ixz="0.0001789000" iyy="0.0005158000" iyz="0.0000006181" izz="0.0003768000"/>
    </inertial>
  </link>
  <joint name="dr_qp/right_middle_tibia_leg" type="fixed">
    <origin rpy="0 0 0" xyz="0.0325 0 0"/>
    <parent link="dr_qp/right_middle_tibia_servo"/>
    <child link="dr_qp/right_middle_tibia_leg"/>
  </joint>
  <gazebo reference="dr_qp/right_middle_tibia_leg">
    <preserveFixedJoint>true</preserveFixedJoint>
  </gazebo>
  <link name="dr_qp/right_middle_tibia_leg">
    <visual>
      <origin rpy="0 0 0" xyz="0 0 0"/>
      <geometry>
        <!--
          Origin is at end servo attachment, 32.5 between servo pivot and this point
         -->
        <mesh filename="package://drqp_description/meshes/Tibia.stl"/>
      </geometry>
      <material name="drqp_black"/>
    </visual>
    <collision>
      <origin rpy="0 0 0" xyz="0 0 0"/>
      <geometry>
        <mesh filename="package://drqp_description/meshes/Tibia-collision.stl"/>
      </geometry>
    </collision>
    <inertial>
      <origin rpy="0 0 0" xyz="0 0 0"/>
      <mass value="0.01"/>
      <inertia ixx="1.6666666666666668e-07" ixy="0.0" ixz="0.0" iyy="1.6666666666666668e-07" iyz="0.0" izz="1.6666666666666668e-07"/>
    </inertial>
  </link>
  <joint name="dr_qp/right_middle_foot" type="fixed">
    <origin rpy="0 0 0" xyz="0.052797 0 -0.088395"/>
    <parent link="dr_qp/right_middle_tibia_leg"/>
    <child link="dr_qp/right_middle_foot_link"/>
  </joint>
  <gazebo reference="dr_qp/right_middle_foot">
    <preserveFixedJoint>true</preserveFixedJoint>
  </gazebo>
  <link name="dr_qp/right_middle_foot_link"/>
  <ros2_control name="dr_qp" type="system">
    <hardware>
      <plugin>drqp_control/a1_16_hardware_interface</plugin>
    </hardware>
    <joint name="dr_qp/right_middle_coxa">
      <command_interface name="position">
        <param name="min">-1.5707963267948966</param>
        <param name="max">1.5707963267948966</param>
      </command_interface>
      <state_interface name="position"/>
    </joint>
    <joint name="dr_qp/right_middle_femur">
      <command_interface name="position">
        <param name="min">-1.710422666954443</param>
        <param name="max">1.5707963267948966</param>
      </command_interface>
      <state_interface name="position"/>
    </joint>
    <joint name="dr_qp/right_middle_tibia">
      <command_interface name="position">
        <param name="min">-1.3962634015954636</param>
        <param name="max">1.9198621771937625</param>
      </command_interface>
      <state_interface name="position"/>
    </joint>
  </ros2_control>
  <joint name="dr_qp/left_back_coxa_servo" type="fixed">
    <origin rpy="0 0 2.356194490192345" xyz="-0.11692 0.06387 0"/>
    <parent link="dr_qp/base_center_link"/>
    <child link="dr_qp/left_back_coxa_servo"/>
  </joint>
  <gazebo reference="dr_qp/left_back_coxa_servo">
    <preserveFixedJoint>true</preserveFixedJoint>
  </gazebo>
  <link name="dr_qp/left_back_coxa_servo">
    <visual>
      <origin rpy="0 0 -1.5707963267948966" xyz="0 0 0"/>
      <geometry>
        <mesh filename="package://drqp_description/meshes/servo.stl"/>
      </geometry>
      <material name="drqp_black"/>
    </visual>
    <collision>
      <origin rpy="0 0 -1.5707963267948966" xyz="0 0 0"/>
      <geometry>
        <mesh filename="package://drqp_description/meshes/servo-collision.stl"/>
      </geometry>
    </collision>
    <inertial>
      <origin rpy="0 0 0" xyz="0.019066 -0.000002 0.006577"/>
      <mass value="0.02471"/>
      <inertia ixx="0.0000215400" ixy="-0.00000000122" ixz="-0.00000192741" iyy="0.00002657000" iyz="-0.00000000001" izz="0.00002925000"/>
    </inertial>
  </link>
  <joint name="dr_qp/left_back_coxa" type="revolute">
    <axis xyz="0 0 1"/>
    <limit effort="3" lower="-1.5707963267948966" upper="1.5707963267948966" velocity="3.141592653589793"/>
    <parent link="dr_qp/left_back_coxa_servo"/>
    <child link="dr_qp/left_back_coxa_f2_link_1"/>
    <!-- <dynamics damping="100" friction="0.1" /> -->
  </joint>
  <gazebo reference="dr_qp/left_back_coxa">
    <dampingFactor>0.04</dampingFactor>
    <implicitSpringDamper>true</implicitSpringDamper>
    <!-- <springStiffness>2</springStiffness> -->
    <springReference>0.01</springReference>
  </gazebo>
  <link name="dr_qp/left_back_coxa_f2_link_1">
    <visual>
      <origin rpy="0 0 1.5707963267948966" xyz="0 0 0"/>
      <geometry>
        <mesh filename="package://drqp_description/meshes/F2.stl"/>
      </geometry>
      <material name="drqp_black"/>
    </visual>
    <collision>
      <origin rpy="0 0 1.5707963267948966" xyz="0 0 0"/>
      <geometry>
        <mesh filename="package://drqp_description/meshes/F2-collision.stl"/>
      </geometry>
    </collision>
    <inertial>
      <origin rpy="0 0 0" xyz="0 0 0"/>
      <mass value="0.01"/>
      <inertia ixx="1.6666666666666668e-07" ixy="0.0" ixz="0.0" iyy="1.6666666666666668e-07" iyz="0.0" izz="1.6666666666666668e-07"/>
    </inertial>
  </link>
  <joint name="dr_qp/left_back_coxa_inner" type="fixed">
    <origin rpy="0 0 0" xyz="0.053 0 0"/>
    <parent link="dr_qp/left_back_coxa_f2_link_1"/>
    <child link="dr_qp/left_back_coxa_f2_link_2"/>
  </joint>
  <gazebo reference="dr_qp/left_back_coxa_inner">
    <preserveFixedJoint>true</preserveFixedJoint>
  </gazebo>
  <link name="dr_qp/left_back_coxa_f2_link_2">
    <visual>
      <origin rpy="0 1.5707963267948966 -1.5707963267948966" xyz="0 0 0"/>
      <geometry>
        <mesh filename="package://drqp_description/meshes/F2.stl"/>
      </geometry>
      <material name="drqp_black"/>
    </visual>
    <collision>
      <origin rpy="0 1.5707963267948966 -1.5707963267948966" xyz="0 0 0"/>
      <geometry>
        <mesh filename="package://drqp_description/meshes/F2-collision.stl"/>
      </geometry>
    </collision>
    <inertial>
      <origin rpy="0 0 0" xyz="0 0 0"/>
      <mass value="0.01"/>
      <inertia ixx="1.6666666666666668e-07" ixy="0.0" ixz="0.0" iyy="1.6666666666666668e-07" iyz="0.0" izz="1.6666666666666668e-07"/>
    </inertial>
  </link>
  <joint name="dr_qp/left_back_femur" type="revolute">
    <axis xyz="0 1 0"/>
    <limit effort="3" lower="-1.710422666954443" upper="1.5707963267948966" velocity="3.141592653589793"/>
    <origin rpy="0 0 0" xyz="0 0 0"/>
    <parent link="dr_qp/left_back_coxa_f2_link_2"/>
    <child link="dr_qp/left_back_femur_servo"/>
    <!-- <dynamics damping="100" friction="0.1" /> -->
  </joint>
  <gazebo reference="dr_qp/left_back_femur">
    <dampingFactor>0.04</dampingFactor>
    <implicitSpringDamper>true</implicitSpringDamper>
    <!-- <springStiffness>2</springStiffness> -->
    <springReference>0.01</springReference>
  </gazebo>
  <link name="dr_qp/left_back_femur_servo">
    <visual>
      <origin rpy="0 1.5707963267948966 1.5707963267948966" xyz="0 0 0"/>
      <geometry>
        <!--
          Origin is at the actuator center
          36mm - distance from actuator center to the center of the holes on the back
         -->
        <mesh filename="package://drqp_description/meshes/servo.stl"/>
      </geometry>
      <material name="drqp_black"/>
    </visual>
    <collision>
      <origin rpy="0 1.5707963267948966 1.5707963267948966" xyz="0 0 0"/>
      <geometry>
        <mesh filename="package://drqp_description/meshes/servo-collision.stl"/>
      </geometry>
    </collision>
    <inertial>
      <origin rpy="0 0 0" xyz="0.019066 -0.000002 0.006577"/>
      <mass value="0.02471"/>
      <inertia ixx="0.0000215400" ixy="-0.00000000122" ixz="-0.00000192741" iyy="0.00002657000" iyz="-0.00000000001" izz="0.00002925000"/>
    </inertial>
  </link>
  <joint name="dr_qp/left_back_femur_inner_1" type="fixed">
    <origin rpy="0 0 0" xyz="0.041499999999999995 0 0"/>
    <parent link="dr_qp/left_back_femur_servo"/>
    <child link="dr_qp/left_back_femur_link_f3"/>
  </joint>
  <gazebo reference="dr_qp/left_back_femur_inner_1">
    <preserveFixedJoint>true</preserveFixedJoint>
  </gazebo>
  <link name="dr_qp/left_back_femur_link_f3">
    <visual>
      <origin rpy="0 1.5707963267948966 1.5707963267948966" xyz="0 0 0"/>
      <geometry>
        <!--
          Origin is at the center of the flat plane
          5.5mm - distance from origin to center of the side mounting holes
         -->
        <mesh filename="package://drqp_description/meshes/F3.stl"/>
      </geometry>
      <material name="drqp_black"/>
    </visual>
    <collision>
      <origin rpy="0 1.5707963267948966 1.5707963267948966" xyz="0 0 0"/>
      <geometry>
        <mesh filename="package://drqp_description/meshes/F3-collision.stl"/>
      </geometry>
    </collision>
    <inertial>
      <origin rpy="0 0 0" xyz="0 0 0"/>
      <mass value="0.01"/>
      <inertia ixx="1.6666666666666668e-07" ixy="0.0" ixz="0.0" iyy="1.6666666666666668e-07" iyz="0.0" izz="1.6666666666666668e-07"/>
    </inertial>
  </link>
  <joint name="dr_qp/left_back_femur_inner_2" type="fixed">
    <origin rpy="0 0 0" xyz="0.023 0 -0.015"/>
    <parent link="dr_qp/left_back_femur_link_f3"/>
    <child link="dr_qp/left_back_femur_link_f1"/>
  </joint>
  <gazebo reference="dr_qp/left_back_femur_inner_2">
    <preserveFixedJoint>true</preserveFixedJoint>
  </gazebo>
  <link name="dr_qp/left_back_femur_link_f1">
    <visual>
      <origin rpy="3.141592653589793 -1.5707963267948966 1.5707963267948966" xyz="0 0 0"/>
      <geometry>
        <!--
          Origin is at the servo mount/pivot
          15.0mm - distance from origin to the center mount holes on the mount plane - x axis
          23.0mm - distance from origin to mount plane - y axis
         -->
        <mesh filename="package://drqp_description/meshes/F1.stl"/>
      </geometry>
      <material name="drqp_black"/>
    </visual>
    <collision>
      <origin rpy="3.141592653589793 -1.5707963267948966 1.5707963267948966" xyz="0 0 0"/>
      <geometry>
        <mesh filename="package://drqp_description/meshes/F1-collision.stl"/>
      </geometry>
    </collision>
    <inertial>
      <origin rpy="0 0 0" xyz="0 0 0"/>
      <mass value="0.01"/>
      <inertia ixx="1.6666666666666668e-07" ixy="0.0" ixz="0.0" iyy="1.6666666666666668e-07" iyz="0.0" izz="1.6666666666666668e-07"/>
    </inertial>
  </link>
  <joint name="dr_qp/left_back_tibia" type="revolute">
    <axis xyz="0 1 0"/>
    <limit effort="3" lower="-1.3962634015954636" upper="1.9198621771937625" velocity="3.141592653589793"/>
    <origin rpy="0 0 0" xyz="0 0 0"/>
    <parent link="dr_qp/left_back_femur_link_f1"/>
    <child link="dr_qp/left_back_tibia_servo"/>
    <!-- <dynamics damping="100" friction="0.1" /> -->
  </joint>
  <gazebo reference="dr_qp/left_back_tibia">
    <dampingFactor>0.04</dampingFactor>
    <implicitSpringDamper>true</implicitSpringDamper>
    <!-- <springStiffness>2</springStiffness> -->
    <springReference>0.01</springReference>
  </gazebo>
  <link name="dr_qp/left_back_tibia_servo">
    <visual>
      <origin rpy="0 1.5707963267948966 1.5707963267948966" xyz="0 0 0"/>
      <geometry>
        <mesh filename="package://drqp_description/meshes/servo.stl"/>
      </geometry>
      <material name="drqp_black"/>
    </visual>
    <collision>
      <origin rpy="0 1.5707963267948966 1.5707963267948966" xyz="0 0 0"/>
      <geometry>
        <mesh filename="package://drqp_description/meshes/servo-collision.stl"/>
      </geometry>
    </collision>
    <inertial>
      <origin rpy="0 0 0" xyz="0.036797 0.000054 -0.011991"/>
      <mass value="0.171825"/>
      <inertia ixx="0.0001762000" ixy="-0.0000014522" ixz="0.0001789000" iyy="0.0005158000" iyz="0.0000006181" izz="0.0003768000"/>
    </inertial>
  </link>
  <joint name="dr_qp/left_back_tibia_leg" type="fixed">
    <origin rpy="0 0 0" xyz="0.0325 0 0"/>
    <parent link="dr_qp/left_back_tibia_servo"/>
    <child link="dr_qp/left_back_tibia_leg"/>
  </joint>
  <gazebo reference="dr_qp/left_back_tibia_leg">
    <preserveFixedJoint>true</preserveFixedJoint>
  </gazebo>
  <link name="dr_qp/left_back_tibia_leg">
    <visual>
      <origin rpy="0 0 0" xyz="0 0 0"/>
      <geometry>
        <!--
          Origin is at end servo attachment, 32.5 between servo pivot and this point
         -->
        <mesh filename="package://drqp_description/meshes/Tibia.stl"/>
      </geometry>
      <material name="drqp_black"/>
    </visual>
    <collision>
      <origin rpy="0 0 0" xyz="0 0 0"/>
      <geometry>
        <mesh filename="package://drqp_description/meshes/Tibia-collision.stl"/>
      </geometry>
    </collision>
    <inertial>
      <origin rpy="0 0 0" xyz="0 0 0"/>
      <mass value="0.01"/>
      <inertia ixx="1.6666666666666668e-07" ixy="0.0" ixz="0.0" iyy="1.6666666666666668e-07" iyz="0.0" izz="1.6666666666666668e-07"/>
    </inertial>
  </link>
  <joint name="dr_qp/left_back_foot" type="fixed">
    <origin rpy="0 0 0" xyz="0.052797 0 -0.088395"/>
    <parent link="dr_qp/left_back_tibia_leg"/>
    <child link="dr_qp/left_back_foot_link"/>
  </joint>
  <gazebo reference="dr_qp/left_back_foot">
    <preserveFixedJoint>true</preserveFixedJoint>
  </gazebo>
  <link name="dr_qp/left_back_foot_link"/>
  <ros2_control name="dr_qp" type="system">
    <hardware>
      <plugin>drqp_control/a1_16_hardware_interface</plugin>
    </hardware>
    <joint name="dr_qp/left_back_coxa">
      <command_interface name="position">
        <param name="min">-1.5707963267948966</param>
        <param name="max">1.5707963267948966</param>
      </command_interface>
      <state_interface name="position"/>
    </joint>
    <joint name="dr_qp/left_back_femur">
      <command_interface name="position">
        <param name="min">-1.710422666954443</param>
        <param name="max">1.5707963267948966</param>
      </command_interface>
      <state_interface name="position"/>
    </joint>
    <joint name="dr_qp/left_back_tibia">
      <command_interface name="position">
        <param name="min">-1.3962634015954636</param>
        <param name="max">1.9198621771937625</param>
      </command_interface>
      <state_interface name="position"/>
    </joint>
  </ros2_control>
  <joint name="dr_qp/right_back_coxa_servo" type="fixed">
    <origin rpy="0 0 -2.356194490192345" xyz="-0.11692 -0.06387 0"/>
    <parent link="dr_qp/base_center_link"/>
    <child link="dr_qp/right_back_coxa_servo"/>
  </joint>
  <gazebo reference="dr_qp/right_back_coxa_servo">
    <preserveFixedJoint>true</preserveFixedJoint>
  </gazebo>
  <link name="dr_qp/right_back_coxa_servo">
    <visual>
      <origin rpy="0 0 -1.5707963267948966" xyz="0 0 0"/>
      <geometry>
        <mesh filename="package://drqp_description/meshes/servo.stl"/>
      </geometry>
      <material name="drqp_black"/>
    </visual>
    <collision>
      <origin rpy="0 0 -1.5707963267948966" xyz="0 0 0"/>
      <geometry>
        <mesh filename="package://drqp_description/meshes/servo-collision.stl"/>
      </geometry>
    </collision>
    <inertial>
      <origin rpy="0 0 0" xyz="0.019066 -0.000002 0.006577"/>
      <mass value="0.02471"/>
      <inertia ixx="0.0000215400" ixy="-0.00000000122" ixz="-0.00000192741" iyy="0.00002657000" iyz="-0.00000000001" izz="0.00002925000"/>
    </inertial>
  </link>
  <joint name="dr_qp/right_back_coxa" type="revolute">
    <axis xyz="0 0 1"/>
    <limit effort="3" lower="-1.5707963267948966" upper="1.5707963267948966" velocity="3.141592653589793"/>
    <parent link="dr_qp/right_back_coxa_servo"/>
    <child link="dr_qp/right_back_coxa_f2_link_1"/>
    <!-- <dynamics damping="100" friction="0.1" /> -->
  </joint>
  <gazebo reference="dr_qp/right_back_coxa">
    <dampingFactor>0.04</dampingFactor>
    <implicitSpringDamper>true</implicitSpringDamper>
    <!-- <springStiffness>2</springStiffness> -->
    <springReference>0.01</springReference>
  </gazebo>
  <link name="dr_qp/right_back_coxa_f2_link_1">
    <visual>
      <origin rpy="0 0 1.5707963267948966" xyz="0 0 0"/>
      <geometry>
        <mesh filename="package://drqp_description/meshes/F2.stl"/>
      </geometry>
      <material name="drqp_black"/>
    </visual>
    <collision>
      <origin rpy="0 0 1.5707963267948966" xyz="0 0 0"/>
      <geometry>
        <mesh filename="package://drqp_description/meshes/F2-collision.stl"/>
      </geometry>
    </collision>
    <inertial>
      <origin rpy="0 0 0" xyz="0 0 0"/>
      <mass value="0.01"/>
      <inertia ixx="1.6666666666666668e-07" ixy="0.0" ixz="0.0" iyy="1.6666666666666668e-07" iyz="0.0" izz="1.6666666666666668e-07"/>
    </inertial>
  </link>
  <joint name="dr_qp/right_back_coxa_inner" type="fixed">
    <origin rpy="0 0 0" xyz="0.053 0 0"/>
    <parent link="dr_qp/right_back_coxa_f2_link_1"/>
    <child link="dr_qp/right_back_coxa_f2_link_2"/>
  </joint>
  <gazebo reference="dr_qp/right_back_coxa_inner">
    <preserveFixedJoint>true</preserveFixedJoint>
  </gazebo>
  <link name="dr_qp/right_back_coxa_f2_link_2">
    <visual>
      <origin rpy="0 1.5707963267948966 -1.5707963267948966" xyz="0 0 0"/>
      <geometry>
        <mesh filename="package://drqp_description/meshes/F2.stl"/>
      </geometry>
      <material name="drqp_black"/>
    </visual>
    <collision>
      <origin rpy="0 1.5707963267948966 -1.5707963267948966" xyz="0 0 0"/>
      <geometry>
        <mesh filename="package://drqp_description/meshes/F2-collision.stl"/>
      </geometry>
    </collision>
    <inertial>
      <origin rpy="0 0 0" xyz="0 0 0"/>
      <mass value="0.01"/>
      <inertia ixx="1.6666666666666668e-07" ixy="0.0" ixz="0.0" iyy="1.6666666666666668e-07" iyz="0.0" izz="1.6666666666666668e-07"/>
    </inertial>
  </link>
  <joint name="dr_qp/right_back_femur" type="revolute">
    <axis xyz="0 1 0"/>
    <limit effort="3" lower="-1.710422666954443" upper="1.5707963267948966" velocity="3.141592653589793"/>
    <origin rpy="0 0 0" xyz="0 0 0"/>
    <parent link="dr_qp/right_back_coxa_f2_link_2"/>
    <child link="dr_qp/right_back_femur_servo"/>
    <!-- <dynamics damping="100" friction="0.1" /> -->
  </joint>
  <gazebo reference="dr_qp/right_back_femur">
    <dampingFactor>0.04</dampingFactor>
    <implicitSpringDamper>true</implicitSpringDamper>
    <!-- <springStiffness>2</springStiffness> -->
    <springReference>0.01</springReference>
  </gazebo>
  <link name="dr_qp/right_back_femur_servo">
    <visual>
      <origin rpy="0 1.5707963267948966 1.5707963267948966" xyz="0 0 0"/>
      <geometry>
        <!--
          Origin is at the actuator center
          36mm - distance from actuator center to the center of the holes on the back
         -->
        <mesh filename="package://drqp_description/meshes/servo.stl"/>
      </geometry>
      <material name="drqp_black"/>
    </visual>
    <collision>
      <origin rpy="0 1.5707963267948966 1.5707963267948966" xyz="0 0 0"/>
      <geometry>
        <mesh filename="package://drqp_description/meshes/servo-collision.stl"/>
      </geometry>
    </collision>
    <inertial>
      <origin rpy="0 0 0" xyz="0.019066 -0.000002 0.006577"/>
      <mass value="0.02471"/>
      <inertia ixx="0.0000215400" ixy="-0.00000000122" ixz="-0.00000192741" iyy="0.00002657000" iyz="-0.00000000001" izz="0.00002925000"/>
    </inertial>
  </link>
  <joint name="dr_qp/right_back_femur_inner_1" type="fixed">
    <origin rpy="0 0 0" xyz="0.041499999999999995 0 0"/>
    <parent link="dr_qp/right_back_femur_servo"/>
    <child link="dr_qp/right_back_femur_link_f3"/>
  </joint>
  <gazebo reference="dr_qp/right_back_femur_inner_1">
    <preserveFixedJoint>true</preserveFixedJoint>
  </gazebo>
  <link name="dr_qp/right_back_femur_link_f3">
    <visual>
      <origin rpy="0 1.5707963267948966 1.5707963267948966" xyz="0 0 0"/>
      <geometry>
        <!--
          Origin is at the center of the flat plane
          5.5mm - distance from origin to center of the side mounting holes
         -->
        <mesh filename="package://drqp_description/meshes/F3.stl"/>
      </geometry>
      <material name="drqp_black"/>
    </visual>
    <collision>
      <origin rpy="0 1.5707963267948966 1.5707963267948966" xyz="0 0 0"/>
      <geometry>
        <mesh filename="package://drqp_description/meshes/F3-collision.stl"/>
      </geometry>
    </collision>
    <inertial>
      <origin rpy="0 0 0" xyz="0 0 0"/>
      <mass value="0.01"/>
      <inertia ixx="1.6666666666666668e-07" ixy="0.0" ixz="0.0" iyy="1.6666666666666668e-07" iyz="0.0" izz="1.6666666666666668e-07"/>
    </inertial>
  </link>
  <joint name="dr_qp/right_back_femur_inner_2" type="fixed">
    <origin rpy="0 0 0" xyz="0.023 0 -0.015"/>
    <parent link="dr_qp/right_back_femur_link_f3"/>
    <child link="dr_qp/right_back_femur_link_f1"/>
  </joint>
  <gazebo reference="dr_qp/right_back_femur_inner_2">
    <preserveFixedJoint>true</preserveFixedJoint>
  </gazebo>
  <link name="dr_qp/right_back_femur_link_f1">
    <visual>
      <origin rpy="3.141592653589793 -1.5707963267948966 1.5707963267948966" xyz="0 0 0"/>
      <geometry>
        <!--
          Origin is at the servo mount/pivot
          15.0mm - distance from origin to the center mount holes on the mount plane - x axis
          23.0mm - distance from origin to mount plane - y axis
         -->
        <mesh filename="package://drqp_description/meshes/F1.stl"/>
      </geometry>
      <material name="drqp_black"/>
    </visual>
    <collision>
      <origin rpy="3.141592653589793 -1.5707963267948966 1.5707963267948966" xyz="0 0 0"/>
      <geometry>
        <mesh filename="package://drqp_description/meshes/F1-collision.stl"/>
      </geometry>
    </collision>
    <inertial>
      <origin rpy="0 0 0" xyz="0 0 0"/>
      <mass value="0.01"/>
      <inertia ixx="1.6666666666666668e-07" ixy="0.0" ixz="0.0" iyy="1.6666666666666668e-07" iyz="0.0" izz="1.6666666666666668e-07"/>
    </inertial>
  </link>
  <joint name="dr_qp/right_back_tibia" type="revolute">
    <axis xyz="0 1 0"/>
    <limit effort="3" lower="-1.3962634015954636" upper="1.9198621771937625" velocity="3.141592653589793"/>
    <origin rpy="0 0 0" xyz="0 0 0"/>
    <parent link="dr_qp/right_back_femur_link_f1"/>
    <child link="dr_qp/right_back_tibia_servo"/>
    <!-- <dynamics damping="100" friction="0.1" /> -->
  </joint>
  <gazebo reference="dr_qp/right_back_tibia">
    <dampingFactor>0.04</dampingFactor>
    <implicitSpringDamper>true</implicitSpringDamper>
    <!-- <springStiffness>2</springStiffness> -->
    <springReference>0.01</springReference>
  </gazebo>
  <link name="dr_qp/right_back_tibia_servo">
    <visual>
      <origin rpy="0 1.5707963267948966 1.5707963267948966" xyz="0 0 0"/>
      <geometry>
        <mesh filename="package://drqp_description/meshes/servo.stl"/>
      </geometry>
      <material name="drqp_black"/>
    </visual>
    <collision>
      <origin rpy="0 1.5707963267948966 1.5707963267948966" xyz="0 0 0"/>
      <geometry>
        <mesh filename="package://drqp_description/meshes/servo-collision.stl"/>
      </geometry>
    </collision>
    <inertial>
      <origin rpy="0 0 0" xyz="0.036797 0.000054 -0.011991"/>
      <mass value="0.171825"/>
      <inertia ixx="0.0001762000" ixy="-0.0000014522" ixz="0.0001789000" iyy="0.0005158000" iyz="0.0000006181" izz="0.0003768000"/>
    </inertial>
  </link>
  <joint name="dr_qp/right_back_tibia_leg" type="fixed">
    <origin rpy="0 0 0" xyz="0.0325 0 0"/>
    <parent link="dr_qp/right_back_tibia_servo"/>
    <child link="dr_qp/right_back_tibia_leg"/>
  </joint>
  <gazebo reference="dr_qp/right_back_tibia_leg">
    <preserveFixedJoint>true</preserveFixedJoint>
  </gazebo>
  <link name="dr_qp/right_back_tibia_leg">
    <visual>
      <origin rpy="0 0 0" xyz="0 0 0"/>
      <geometry>
        <!--
          Origin is at end servo attachment, 32.5 between servo pivot and this point
         -->
        <mesh filename="package://drqp_description/meshes/Tibia.stl"/>
      </geometry>
      <material name="drqp_black"/>
    </visual>
    <collision>
      <origin rpy="0 0 0" xyz="0 0 0"/>
      <geometry>
        <mesh filename="package://drqp_description/meshes/Tibia-collision.stl"/>
      </geometry>
    </collision>
    <inertial>
      <origin rpy="0 0 0" xyz="0 0 0"/>
      <mass value="0.01"/>
      <inertia ixx="1.6666666666666668e-07" ixy="0.0" ixz="0.0" iyy="1.6666666666666668e-07" iyz="0.0" izz="1.6666666666666668e-07"/>
    </inertial>
  </link>
  <joint name="dr_qp/right_back_foot" type="fixed">
    <origin rpy="0 0 0" xyz="0.052797 0 -0.088395"/>
    <parent link="dr_qp/right_back_tibia_leg"/>
    <child link="dr_qp/right_back_foot_link"/>
  </joint>
  <gazebo reference="dr_qp/right_back_foot">
    <preserveFixedJoint>true</preserveFixedJoint>
  </gazebo>
  <link name="dr_qp/right_back_foot_link"/>
  <ros2_control name="dr_qp" type="system">
    <hardware>
      <plugin>drqp_control/a1_16_hardware_interface</plugin>
    </hardware>
    <joint name="dr_qp/right_back_coxa">
      <command_interface name="position">
        <param name="min">-1.5707963267948966</param>
        <param name="max">1.5707963267948966</param>
      </command_interface>
      <state_interface name="position"/>
    </joint>
    <joint name="dr_qp/right_back_femur">
      <command_interface name="position">
        <param name="min">-1.710422666954443</param>
        <param name="max">1.5707963267948966</param>
      </command_interface>
      <state_interface name="position"/>
    </joint>
    <joint name="dr_qp/right_back_tibia">
      <command_interface name="position">
        <param name="min">-1.3962634015954636</param>
        <param name="max">1.9198621771937625</param>
      </command_interface>
      <state_interface name="position"/>
    </joint>
  </ros2_control>
  <link name="world"/>
  <joint name="world_to_base_link=" type="fixed">
    <origin rpy="0 0 0" xyz="0 0 0.085"/>
    <parent link="world"/>
    <child link="dr_qp/base_link"/>
  </joint>
  <gazebo reference="">
    <self_collide>1</self_collide>
    <!-- Params copied from https://www.youtube.com/watch?v=Gp3DF97yN7k&list=PL_0ePxMRfT22elbjPCf36MS02d6TK2sSk&index=1 -->
    <mu1>50</mu1>
    <mu2>25</mu2>
    <kp>25000</kp>
    <kd>0.05</kd>
  </gazebo>
</robot>
'
